Workbook

Sheet Main
A1: Index | B1: Date | C1: Category | D1: Sub Category | E1: =CONCATENATE("Amount (", -SUM(E2:E1032) ,")") -> Amount (39050.57) | F1: =CONCATENATE("Balance (", F2+SUM(E2:E1032) ,")") -> Balance (62226.34) | G1: Notes | H1: Groups | I1: Month | J1: Year | K1: Year-Month
A2: 1 | B2: 45505 | E2: 0 | F2: =101276.91 -> 101276.91 | I2: =IF(ISBLANK(A2), "", MONTH(B2)) -> 8 | J2: =IF(ISBLANK(A2), "", YEAR(B2)) -> 2024 | K2: =IF(ISBLANK(A2), "", CONCATENATE(J2," - ",I2)) -> 2024 - 8
A3: 2 | B3: 45505 | C3: Misc | D3: Personal | E3: =-300 -> -300 | F3: =IF(ISBLANK(A3),"", F2+E3) -> 100976.91 | G3: License | I3: =IF(ISBLANK(A3), "", MONTH(B3)) -> 8 | J3: =IF(ISBLANK(A3), "", YEAR(B3)) -> 2024 | K3: =IF(ISBLANK(A3), "", CONCATENATE(J3," - ",I3)) -> 2024 - 8
A4: 3 | B4: 45505 | C4: Lend | D4: Others | E4: =-1500 -> -1500 | F4: =IF(ISBLANK(A4),"", F3+E4) -> 99476.91 | G4: Snehith | H4: G6 | I4: =IF(ISBLANK(A4), "", MONTH(B4)) -> 8 | J4: =IF(ISBLANK(A4), "", YEAR(B4)) -> 2024 | K4: =IF(ISBLANK(A4), "", CONCATENATE(J4," - ",I4)) -> 2024 - 8
A5: 4 | B5: 45505 | C5: Shop | D5: Personal | E5: =-531 -> -531 | F5: =IF(ISBLANK(A5),"", F4+E5) -> 98945.91 | G5: Convocation Shirt | I5: =IF(ISBLANK(A5), "", MONTH(B5)) -> 8 | J5: =IF(ISBLANK(A5), "", YEAR(B5)) -> 2024 | K5: =IF(ISBLANK(A5), "", CONCATENATE(J5," - ",I5)) -> 2024 - 8
A6: 5 | B6: 45505 | C6: Shop | D6: Personal | E6: =-500 -> -500 | F6: =IF(ISBLANK(A6),"", F5+E6) -> 98445.91 | G6: Convocation Shirt | I6: =IF(ISBLANK(A6), "", MONTH(B6)) -> 8 | J6: =IF(ISBLANK(A6), "", YEAR(B6)) -> 2024 | K6: =IF(ISBLANK(A6), "", CONCATENATE(J6," - ",I6)) -> 2024 - 8
A7: 6 | B7: 45505 | C7: Food | D7: Personal | E7: =-551 -> -551 | F7: =IF(ISBLANK(A7),"", F6+E7) -> 97894.91 | G7: Truffles Order | I7: =IF(ISBLANK(A7), "", MONTH(B7)) -> 8 | J7: =IF(ISBLANK(A7), "", YEAR(B7)) -> 2024 | K7: =IF(ISBLANK(A7), "", CONCATENATE(J7," - ",I7)) -> 2024 - 8
A8: 7 | B8: 45506 | C8: Misc | D8: Family | E8: =-200 -> -200 | F8: =IF(ISBLANK(A8),"", F7+E8) -> 97694.91 | G8: Mom's Kitty | I8: =IF(ISBLANK(A8), "", MONTH(B8)) -> 8 | J8: =IF(ISBLANK(A8), "", YEAR(B8)) -> 2024 | K8: =IF(ISBLANK(A8), "", CONCATENATE(J8," - ",I8)) -> 2024 - 8
A9: 8 | B9: 45510 | C9: Fuel | D9: Personal | E9: -393.91 | F9: =IF(ISBLANK(A9),"", F8+E9) -> 97301 | G9: Scooty | I9: =IF(ISBLANK(A9), "", MONTH(B9)) -> 8 | J9: =IF(ISBLANK(A9), "", YEAR(B9)) -> 2024 | K9: =IF(ISBLANK(A9), "", CONCATENATE(J9," - ",I9)) -> 2024 - 8
A10: 9 | B10: 45510 | C10: Split Return | D10: Others | E10: 8692 | F10: =IF(ISBLANK(A10),"", F9+E10) -> 105993 | G10: Bhavye Ticket | I10: =IF(ISBLANK(A10), "", MONTH(B10)) -> 8 | J10: =IF(ISBLANK(A10), "", YEAR(B10)) -> 2024 | K10: =IF(ISBLANK(A10), "", CONCATENATE(J10," - ",I10)) -> 2024 - 8
A11: 10 | B11: 45511 | C11: Food | D11: Family | E11: -245 | F11: =IF(ISBLANK(A11),"", F10+E11) -> 105748 | G11: Chat | I11: =IF(ISBLANK(A11), "", MONTH(B11)) -> 8 | J11: =IF(ISBLANK(A11), "", YEAR(B11)) -> 2024 | K11: =IF(ISBLANK(A11), "", CONCATENATE(J11," - ",I11)) -> 2024 - 8
A12: 11 | B12: 45512 | C12: Shop | D12: Family | E12: -4999 | F12: =IF(ISBLANK(A12),"", F11+E12) -> 100749 | G12: Muskan | I12: =IF(ISBLANK(A12), "", MONTH(B12)) -> 8 | J12: =IF(ISBLANK(A12), "", YEAR(B12)) -> 2024 | K12: =IF(ISBLANK(A12), "", CONCATENATE(J12," - ",I12)) -> 2024 - 8
A13: 12 | B13: 45512 | C13: Shop | D13: Family | E13: -5998 | F13: =IF(ISBLANK(A13),"", F12+E13) -> 94751 | G13: Muskan | I13: =IF(ISBLANK(A13), "", MONTH(B13)) -> 8 | J13: =IF(ISBLANK(A13), "", YEAR(B13)) -> 2024 | K13: =IF(ISBLANK(A13), "", CONCATENATE(J13," - ",I13)) -> 2024 - 8
A14: 13 | B14: 45513 | C14: Shop | D14: Personal | E14: -2490 | F14: =IF(ISBLANK(A14),"", F13+E14) -> 92261 | G14: Pant Project | I14: =IF(ISBLANK(A14), "", MONTH(B14)) -> 8 | J14: =IF(ISBLANK(A14), "", YEAR(B14)) -> 2024 | K14: =IF(ISBLANK(A14), "", CONCATENATE(J14," - ",I14)) -> 2024 - 8
A15: 14 | B15: 45513 | C15: Shop | D15: Others | E15: -1416 | F15: =IF(ISBLANK(A15),"", F14+E15) -> 90845 | G15: Shreyas Gift | I15: =IF(ISBLANK(A15), "", MONTH(B15)) -> 8 | J15: =IF(ISBLANK(A15), "", YEAR(B15)) -> 2024 | K15: =IF(ISBLANK(A15), "", CONCATENATE(J15," - ",I15)) -> 2024 - 8
A16: 15 | B16: 45514 | C16: Split Return | D16: Others | E16: 300 | F16: =IF(ISBLANK(A16),"", F15+E16) -> 91145 | G16: Imtiyaz, Shreyas Gift | I16: =IF(ISBLANK(A16), "", MONTH(B16)) -> 8 | J16: =IF(ISBLANK(A16), "", YEAR(B16)) -> 2024 | K16: =IF(ISBLANK(A16), "", CONCATENATE(J16," - ",I16)) -> 2024 - 8
A17: 16 | B17: 45514 | C17: Travel | D17: Personal | E17: -131 | F17: =IF(ISBLANK(A17),"", F16+E17) -> 91014 | G17: Auto | I17: =IF(ISBLANK(A17), "", MONTH(B17)) -> 8 | J17: =IF(ISBLANK(A17), "", YEAR(B17)) -> 2024 | K17: =IF(ISBLANK(A17), "", CONCATENATE(J17," - ",I17)) -> 2024 - 8
A18: 17 | B18: 45514 | C18: Shop | D18: Others | E18: -3117 | F18: =IF(ISBLANK(A18),"", F17+E18) -> 87897 | G18: TEDx Photos | I18: =IF(ISBLANK(A18), "", MONTH(B18)) -> 8 | J18: =IF(ISBLANK(A18), "", YEAR(B18)) -> 2024 | K18: =IF(ISBLANK(A18), "", CONCATENATE(J18," - ",I18)) -> 2024 - 8
A19: 18 | B19: 45514 | C19: Travel | D19: Personal | E19: -190 | F19: =IF(ISBLANK(A19),"", F18+E19) -> 87707 | G19: Auto | I19: =IF(ISBLANK(A19), "", MONTH(B19)) -> 8 | J19: =IF(ISBLANK(A19), "", YEAR(B19)) -> 2024 | K19: =IF(ISBLANK(A19), "", CONCATENATE(J19," - ",I19)) -> 2024 - 8
A20: 19 | B20: 45514 | C20: Food | D20: Personal | E20: -98 | F20: =IF(ISBLANK(A20),"", F19+E20) -> 87609 | G20: Lunch | I20: =IF(ISBLANK(A20), "", MONTH(B20)) -> 8 | J20: =IF(ISBLANK(A20), "", YEAR(B20)) -> 2024 | K20: =IF(ISBLANK(A20), "", CONCATENATE(J20," - ",I20)) -> 2024 - 8
... A26: 25 | B26: 45515 | C26: Shop | D26: Family | E26: -3422 | F26: =IF(ISBLANK(A26),"", F25+E26) -> 53454 | G26: Mandala Frame | I26: =IF(ISBLANK(A26), "", MONTH(B26)) -> 8 | J26: =IF(ISBLANK(A26), "", YEAR(B26)) -> 2024 | K26: =IF(ISBLANK(A26), "", CONCATENATE(J26," - ",I26)) -> 2024 - 8
A27: 26 | B27: 45515 | C27: Fun | D27: Personal, Others | E27: -7996 | F27: =IF(ISBLANK(A27),"", F26+E27) -> 45458 | G27: Kanva Camp | H27: G1 | I27: =IF(ISBLANK(A27), "", MONTH(B27)) -> 8 | J27: =IF(ISBLANK(A27), "", YEAR(B27)) -> 2024 | K27: =IF(ISBLANK(A27), "", CONCATENATE(J27," - ",I27)) -> 2024 - 8
A28: 27 | B28: 45515 | C28: Travel | D28: Personal | E28: -456 | F28: =IF(ISBLANK(A28),"", F27+E28) -> 45002 | G28: Auto | I28: =IF(ISBLANK(A28), "", MONTH(B28)) -> 8 | J28: =IF(ISBLANK(A28), "", YEAR(B28)) -> 2024 | K28: =IF(ISBLANK(A28), "", CONCATENATE(J28," - ",I28)) -> 2024 - 8
A29: 28 | B29: 45516 | C29: Shop | D29: Personal | E29: -1449 | F29: =IF(ISBLANK(A29),"", F28+E29) -> 43553 | G29: Power bank | I29: =IF(ISBLANK(A29), "", MONTH(B29)) -> 8 | J29: =IF(ISBLANK(A29), "", YEAR(B29)) -> 2024 | K29: =IF(ISBLANK(A29), "", CONCATENATE(J29," - ",I29)) -> 2024 - 8
A30: 29 | B30: 45516 | C30: Transfer | D30: Family | E30: -15000 | F30: =IF(ISBLANK(A30),"", F29+E30) -> 28553 | G30: Muskaan | I30: =IF(ISBLANK(A30), "", MONTH(B30)) -> 8 | J30: =IF(ISBLANK(A30), "", YEAR(B30)) -> 2024 | K30: =IF(ISBLANK(A30), "", CONCATENATE(J30," - ",I30)) -> 2024 - 8
A31: 30 | B31: 45518 | C31: Travel | D31: Personal | E31: -192 | F31: =IF(ISBLANK(A31),"", F30+E31) -> 28361 | G31: Auto | I31: =IF(ISBLANK(A31), "", MONTH(B31)) -> 8 | J31: =IF(ISBLANK(A31), "", YEAR(B31)) -> 2024 | K31: =IF(ISBLANK(A31), "", CONCATENATE(J31," - ",I31)) -> 2024 - 8
A32: 31 | B32: 45518 | C32: Travel | D32: Personal | E32: -42.75 | F32: =IF(ISBLANK(A32),"", F31+E32) -> 28318.25 | G32: Metro | I32: =IF(ISBLANK(A32), "", MONTH(B32)) -> 8 | J32: =IF(ISBLANK(A32), "", YEAR(B32)) -> 2024 | K32: =IF(ISBLANK(A32), "", CONCATENATE(J32," - ",I32)) -> 2024 - 8
A33: 32 | B33: 45518 | C33: Travel | D33: Personal | E33: -128 | F33: =IF(ISBLANK(A33),"", F32+E33) -> 28190.25 | G33: Auto | I33: =IF(ISBLANK(A33), "", MONTH(B33)) -> 8 | J33: =IF(ISBLANK(A33), "", YEAR(B33)) -> 2024 | K33: =IF(ISBLANK(A33), "", CONCATENATE(J33," - ",I33)) -> 2024 - 8
A34: 33 | B34: 45518 | C34: Travel | D34: Personal | E34: -17.1 | F34: =IF(ISBLANK(A34),"", F33+E34) -> 28173.15 | G34: Metro | I34: =IF(ISBLANK(A34), "", MONTH(B34)) -> 8 | J34: =IF(ISBLANK(A34), "", YEAR(B34)) -> 2024 | K34: =IF(ISBLANK(A34), "", CONCATENATE(J34," - ",I34)) -> 2024 - 8
A35: 34 | B35: 45518 | C35: Travel | D35: Personal | E35: -160 | F35: =IF(ISBLANK(A35),"", F34+E35) -> 28013.15 | G35: Auto | I35: =IF(ISBLANK(A35), "", MONTH(B35)) -> 8 | J35: =IF(ISBLANK(A35), "", YEAR(B35)) -> 2024 | K35: =IF(ISBLANK(A35), "", CONCATENATE(J35," - ",I35)) -> 2024 - 8
A36: 35 | B36: 45518 | C36: Food | D36: Personal, Others | E36: -995 | F36: =IF(ISBLANK(A36),"", F35+E36) -> 27018.15 | G36: Bhavye Lebanese | H36: G2 | I36: =IF(ISBLANK(A36), "", MONTH(B36)) -> 8 | J36: =IF(ISBLANK(A36), "", YEAR(B36)) -> 2024 | K36: =IF(ISBLANK(A36), "", CONCATENATE(J36," - ",I36)) -> 2024 - 8
A37: 36 | B37: 45518 | C37: Food | D37: Others | E37: -93 | F37: =IF(ISBLANK(A37),"", F36+E37) -> 26925.15 | G37: Bhavye Mirinda | H37: G2 | I37: =IF(ISBLANK(A37), "", MONTH(B37)) -> 8 | J37: =IF(ISBLANK(A37), "", YEAR(B37)) -> 2024 | K37: =IF(ISBLANK(A37), "", CONCATENATE(J37," - ",I37)) -> 2024 - 8
A38: 37 | B38: 45518 | C38: Travel | D38: Personal | E38: -47.5 | F38: =IF(ISBLANK(A38),"", F37+E38) -> 26877.65 | G38: Metro | I38: =IF(ISBLANK(A38), "", MONTH(B38)) -> 8 | J38: =IF(ISBLANK(A38), "", YEAR(B38)) -> 2024 | K38: =IF(ISBLANK(A38), "", CONCATENATE(J38," - ",I38)) -> 2024 - 8
A39: 38 | B39: 45518 | C39: Travel | D39: Personal | E39: -79.8 | F39: =IF(ISBLANK(A39),"", F38+E39) -> 26797.85 | G39: Metro | H39: G2 | I39: =IF(ISBLANK(A39), "", MONTH(B39)) -> 8 | J39: =IF(ISBLANK(A39), "", YEAR(B39)) -> 2024 | K39: =IF(ISBLANK(A39), "", CONCATENATE(J39," - ",I39)) -> 2024 - 8
A40: 39 | B40: 45518 | C40: Travel | D40: Personal | E40: -122 | F40: =IF(ISBLANK(A40),"", F39+E40) -> 26675.85 | G40: Auto | H40: G2 | I40: =IF(ISBLANK(A40), "", MONTH(B40)) -> 8 | J40: =IF(ISBLANK(A40), "", YEAR(B40)) -> 2024 | K40: =IF(ISBLANK(A40), "", CONCATENATE(J40," - ",I40)) -> 2024 - 8
A41: 40 | B41: 45518 | C41: Shop | D41: Personal | E41: -445 | F41: =IF(ISBLANK(A41),"", F40+E41) -> 26230.85 | G41: Trip Snacks | H41: G1 | I41: =IF(ISBLANK(A41), "", MONTH(B41)) -> 8 | J41: =IF(ISBLANK(A41), "", YEAR(B41)) -> 2024 | K41: =IF(ISBLANK(A41), "", CONCATENATE(J41," - ",I41)) -> 2024 - 8
A42: 41 | B42: 45518 | C42: Monthly Bill | D42: Personal | E42: -649 | F42: =IF(ISBLANK(A42),"", F41+E42) -> 25581.85 | G42: Netflix | H42: G5 | I42: =IF(ISBLANK(A42), "", MONTH(B42)) -> 8 | J42: =IF(ISBLANK(A42), "", YEAR(B42)) -> 2024 | K42: =IF(ISBLANK(A42), "", CONCATENATE(J42," - ",I42)) -> 2024 - 8
A43: 42 | B43: 45520 | C43: Food | D43: Personal, Others | E43: -6777 | F43: =IF(ISBLANK(A43),"", F42+E43) -> 18804.85 | G43: Oia After Kanva | H43: G7 | I43: =IF(ISBLANK(A43), "", MONTH(B43)) -> 8 | J43: =IF(ISBLANK(A43), "", YEAR(B43)) -> 2024 | K43: =IF(ISBLANK(A43), "", CONCATENATE(J43," - ",I43)) -> 2024 - 8
A44: 43 | B44: 45520 | C44: Misc | D44: Personal, Others | E44: -75 | F44: =IF(ISBLANK(A44),"", F43+E44) -> 18729.85 | G44: Eatables | I44: =IF(ISBLANK(A44), "", MONTH(B44)) -> 8 | J44: =IF(ISBLANK(A44), "", YEAR(B44)) -> 2024 | K44: =IF(ISBLANK(A44), "", CONCATENATE(J44," - ",I44)) -> 2024 - 8
A45: 44 | B45: 45520 | C45: Misc | D45: Personal | E45: -100 | F45: =IF(ISBLANK(A45),"", F44+E45) -> 18629.85 | G45: Haircut | I45: =IF(ISBLANK(A45), "", MONTH(B45)) -> 8 | J45: =IF(ISBLANK(A45), "", YEAR(B45)) -> 2024 | K45: =IF(ISBLANK(A45), "", CONCATENATE(J45," - ",I45)) -> 2024 - 8
...

Sheet Chart Table
A1: Year | B1: Month | C1: Unique Ref | D1: Fuel | E1: Travel | F1: SIP | G1: Misc | H1: Lend | I1: Fun | J1: Transfer | K1: Shop | L1: Food | M1: Monthly Bill | N1: Yearly Bill | O1: Rent | P1: Medicine | Q1: Lend Return | R1: Split Return | S1: Salary | T1: Tax Return | U1: Cashback | V1: Starter | W1: Total Debit | X1: Total Credit | Y1: Desert
A2: =IFERROR(__xludf.DUMMYFUNCTION("SPLIT(C2, "" - "")"),2024.0) -> 2024 | B2: =IFERROR(__xludf.DUMMYFUNCTION("""COMPUTED_VALUE"""),8.0) -> 8 | C2: {=UNIQUE(Main!K2:K1000)} -> 2024 - 8 | D2: =SUMIFS(Main!$E$2:$E1000,Main!$I$2:$I1000, "="&$B2, Main!$J$2:$J1000, "="&$A2, Main!$C$2:$C1000, "="&D$1) -> -393.91 | E2: =SUMIFS(Main!$E$2:$E1000,Main!$I$2:$I1000, "="&$B2, Main!$J$2:$J1000, "="&$A2, Main!$C$2:$C1000, "="&E$1) -> -5985.39 | F2: =SUMIFS(Main!$E$2:$E1000,Main!$I$2:$I1000, "="&$B2, Main!$J$2:$J1000, "="&$A2, Main!$C$2:$C1000, "="&F$1) -> -6000 | G2: =SUMIFS(Main!$E$2:$E1000,Main!$I$2:$I1000, "="&$B2, Main!$J$2:$J1000, "="&$A2, Main!$C$2:$C1000, "="&G$1) -> -875 | H2: =SUMIFS(Main!$E$2:$E1000,Main!$I$2:$I1000, "="&$B2, Main!$J$2:$J1000, "="&$A2, Main!$C$2:$C1000, "="&H$1) -> -1500 | I2: =SUMIFS(Main!$E$2:$E1000,Main!$I$2:$I1000, "="&$B2, Main!$J$2:$J1000, "="&$A2, Main!$C$2:$C1000, "="&I$1) -> -10696 | J2: =SUMIFS(Main!$E$2:$E1000,Main!$I$2:$I1000, "="&$B2, Main!$J$2:$J1000, "="&$A2, Main!$C$2:$C1000, "="&J$1) -> -45000 | K2: =SUMIFS(Main!$E$2:$E1000,Main!$I$2:$I1000, "="&$B2, Main!$J$2:$J1000, "="&$A2, Main!$C$2:$C1000, "="&K$1) -> -46605 | ... U2: =SUMIFS(Main!$E$2:$E1000,Main!$I$2:$I1000, "="&$B2, Main!$J$2:$J1000, "="&$A2, Main!$C$2:$C1000, "="&U$1) -> 0 | V2: =101276.91 -> 101276.91 | W2: =SUMIF($B2:$U2, "<0") -> -147663.97 | X2: =SUMIF($B2:$U2, ">0") -> 86509 | Y2: =V2+W2+X2 -> 40121.94
A3: =IFERROR(__xludf.DUMMYFUNCTION("SPLIT(C3, "" - "")"),2024.0) -> 2024 | B3: =IFERROR(__xludf.DUMMYFUNCTION("""COMPUTED_VALUE"""),9.0) -> 9 | C3: 2024 - 9 | D3: =SUMIFS(Main!$E$2:$E1000,Main!$I$2:$I1000, "="&$B3, Main!$J$2:$J1000, "="&$A3, Main!$C$2:$C1000, "="&D$1) -> -1879.7 | E3: =SUMIFS(Main!$E$2:$E1000,Main!$I$2:$I1000, "="&$B3, Main!$J$2:$J1000, "="&$A3, Main!$C$2:$C1000, "="&E$1) -> -1142.17 | F3: =SUMIFS(Main!$E$2:$E1000,Main!$I$2:$I1000, "="&$B3, Main!$J$2:$J1000, "="&$A3, Main!$C$2:$C1000, "="&F$1) -> -2000 | G3: =SUMIFS(Main!$E$2:$E1000,Main!$I$2:$I1000, "="&$B3, Main!$J$2:$J1000, "="&$A3, Main!$C$2:$C1000, "="&G$1) -> -1481 | H3: =SUMIFS(Main!$E$2:$E1000,Main!$I$2:$I1000, "="&$B3, Main!$J$2:$J1000, "="&$A3, Main!$C$2:$C1000, "="&H$1) -> 0 | I3: =SUMIFS(Main!$E$2:$E1000,Main!$I$2:$I1000, "="&$B3, Main!$J$2:$J1000, "="&$A3, Main!$C$2:$C1000, "="&I$1) -> -1141.6 | J3: =SUMIFS(Main!$E$2:$E1000,Main!$I$2:$I1000, "="&$B3, Main!$J$2:$J1000, "="&$A3, Main!$C$2:$C1000, "="&J$1) -> -100000 | K3: =SUMIFS(Main!$E$2:$E1000,Main!$I$2:$I1000, "="&$B3, Main!$J$2:$J1000, "="&$A3, Main!$C$2:$C1000, "="&K$1) -> -3508 | ... U3: =SUMIFS(Main!$E$2:$E1000,Main!$I$2:$I1000, "="&$B3, Main!$J$2:$J1000, "="&$A3, Main!$C$2:$C1000, "="&U$1) -> 0 | V3: =Y2 -> 40121.94 | W3: =SUMIF($B3:$U3, "<0") -> -124809.43 | X3: =SUMIF($B3:$U3, ">0") -> 115554.08 | Y3: =V3+W3+X3 -> 30866.59
A4: =IFERROR(__xludf.DUMMYFUNCTION("SPLIT(C4, "" - "")"),2024.0) -> 2024 | B4: =IFERROR(__xludf.DUMMYFUNCTION("""COMPUTED_VALUE"""),10.0) -> 10 | C4: 2024 - 10 | D4: =SUMIFS(Main!$E$2:$E1000,Main!$I$2:$I1000, "="&$B4, Main!$J$2:$J1000, "="&$A4, Main!$C$2:$C1000, "="&D$1) -> -321.95 | E4: =SUMIFS(Main!$E$2:$E1000,Main!$I$2:$I1000, "="&$B4, Main!$J$2:$J1000, "="&$A4, Main!$C$2:$C1000, "="&E$1) -> -29124 | F4: =SUMIFS(Main!$E$2:$E1000,Main!$I$2:$I1000, "="&$B4, Main!$J$2:$J1000, "="&$A4, Main!$C$2:$C1000, "="&F$1) -> -2100 | G4: =SUMIFS(Main!$E$2:$E1000,Main!$I$2:$I1000, "="&$B4, Main!$J$2:$J1000, "="&$A4, Main!$C$2:$C1000, "="&G$1) -> -600 | H4: =SUMIFS(Main!$E$2:$E1000,Main!$I$2:$I1000, "="&$B4, Main!$J$2:$J1000, "="&$A4, Main!$C$2:$C1000, "="&H$1) -> -59 | I4: =SUMIFS(Main!$E$2:$E1000,Main!$I$2:$I1000, "="&$B4, Main!$J$2:$J1000, "="&$A4, Main!$C$2:$C1000, "="&I$1) -> -16212.84 | J4: =SUMIFS(Main!$E$2:$E1000,Main!$I$2:$I1000, "="&$B4, Main!$J$2:$J1000, "="&$A4, Main!$C$2:$C1000, "="&J$1) -> -25000 | K4: =SUMIFS(Main!$E$2:$E1000,Main!$I$2:$I1000, "="&$B4, Main!$J$2:$J1000, "="&$A4, Main!$C$2:$C1000, "="&K$1) -> -36363.39 | ... U4: =SUMIFS(Main!$E$2:$E1000,Main!$I$2:$I1000, "="&$B4, Main!$J$2:$J1000, "="&$A4, Main!$C$2:$C1000, "="&U$1) -> 0 | V4: =Y3 -> 30866.59 | W4: =SUMIF($B4:$U4, "<0") -> -116748.72 | X4: =SUMIF($B4:$U4, ">0") -> 86015.53 | Y4: =V4+W4+X4 -> 133.4
A5: =IFERROR(__xludf.DUMMYFUNCTION("SPLIT(C5, "" - "")"),2024.0) -> 2024 | B5: =IFERROR(__xludf.DUMMYFUNCTION("""COMPUTED_VALUE"""),11.0) -> 11 | C5: 2024 - 11 | D5: =SUMIFS(Main!$E$2:$E1000,Main!$I$2:$I1000, "="&$B5, Main!$J$2:$J1000, "="&$A5, Main!$C$2:$C1000, "="&D$1) -> 0 | E5: =SUMIFS(Main!$E$2:$E1000,Main!$I$2:$I1000, "="&$B5, Main!$J$2:$J1000, "="&$A5, Main!$C$2:$C1000, "="&E$1) -> -87 | F5: =SUMIFS(Main!$E$2:$E1000,Main!$I$2:$I1000, "="&$B5, Main!$J$2:$J1000, "="&$A5, Main!$C$2:$C1000, "="&F$1) -> -2100 | G5: =SUMIFS(Main!$E$2:$E1000,Main!$I$2:$I1000, "="&$B5, Main!$J$2:$J1000, "="&$A5, Main!$C$2:$C1000, "="&G$1) -> -1527 | H5: =SUMIFS(Main!$E$2:$E1000,Main!$I$2:$I1000, "="&$B5, Main!$J$2:$J1000, "="&$A5, Main!$C$2:$C1000, "="&H$1) -> -11059 | I5: =SUMIFS(Main!$E$2:$E1000,Main!$I$2:$I1000, "="&$B5, Main!$J$2:$J1000, "="&$A5, Main!$C$2:$C1000, "="&I$1) -> -31609 | J5: =SUMIFS(Main!$E$2:$E1000,Main!$I$2:$I1000, "="&$B5, Main!$J$2:$J1000, "="&$A5, Main!$C$2:$C1000, "="&J$1) -> -14000 | K5: =SUMIFS(Main!$E$2:$E1000,Main!$I$2:$I1000, "="&$B5, Main!$J$2:$J1000, "="&$A5, Main!$C$2:$C1000, "="&K$1) -> -12806.64 | ... U5: =SUMIFS(Main!$E$2:$E1000,Main!$I$2:$I1000, "="&$B5, Main!$J$2:$J1000, "="&$A5, Main!$C$2:$C1000, "="&U$1) -> 0 | V5: =Y4 -> 133.4 | W5: =SUMIF($B5:$U5, "<0") -> -79312.3 | X5: =SUMIF($B5:$U5, ">0") -> 81134 | Y5: =V5+W5+X5 -> 1955.1
A6: =IFERROR(__xludf.DUMMYFUNCTION("SPLIT(C6, "" - "")"),2024.0) -> 2024 | B6: =IFERROR(__xludf.DUMMYFUNCTION("""COMPUTED_VALUE"""),12.0) -> 12 | C6: 2024 - 12 | D6: =SUMIFS(Main!$E$2:$E1000,Main!$I$2:$I1000, "="&$B6, Main!$J$2:$J1000, "="&$A6, Main!$C$2:$C1000, "="&D$1) -> -300 | E6: =SUMIFS(Main!$E$2:$E1000,Main!$I$2:$I1000, "="&$B6, Main!$J$2:$J1000, "="&$A6, Main!$C$2:$C1000, "="&E$1) -> -93 | F6: =SUMIFS(Main!$E$2:$E1000,Main!$I$2:$I1000, "="&$B6, Main!$J$2:$J1000, "="&$A6, Main!$C$2:$C1000, "="&F$1) -> 17060.19 | G6: =SUMIFS(Main!$E$2:$E1000,Main!$I$2:$I1000, "="&$B6, Main!$J$2:$J1000, "="&$A6, Main!$C$2:$C1000, "="&G$1) -> -9394 | H6: =SUMIFS(Main!$E$2:$E1000,Main!$I$2:$I1000, "="&$B6, Main!$J$2:$J1000, "="&$A6, Main!$C$2:$C1000, "="&H$1) -> -10000 | I6: =SUMIFS(Main!$E$2:$E1000,Main!$I$2:$I1000, "="&$B6, Main!$J$2:$J1000, "="&$A6, Main!$C$2:$C1000, "="&I$1) -> -3200 | J6: =SUMIFS(Main!$E$2:$E1000,Main!$I$2:$I1000, "="&$B6, Main!$J$2:$J1000, "="&$A6, Main!$C$2:$C1000, "="&J$1) -> -40000 | K6: =SUMIFS(Main!$E$2:$E1000,Main!$I$2:$I1000, "="&$B6, Main!$J$2:$J1000, "="&$A6, Main!$C$2:$C1000, "="&K$1) -> -32963.05 | ... U6: =SUMIFS(Main!$E$2:$E1000,Main!$I$2:$I1000, "="&$B6, Main!$J$2:$J1000, "="&$A6, Main!$C$2:$C1000, "="&U$1) -> 0 | V6: =Y5 -> 1955.1 | W6: =SUMIF($B6:$U6, "<0") -> -106172.51 | X6: =SUMIF($B6:$U6, ">0") -> 202885.19 | Y6: =V6+W6+X6 -> 98667.78
A7: =IFERROR(__xludf.DUMMYFUNCTION("SPLIT(C7, "" - "")"),2025.0) -> 2025 | B7: =IFERROR(__xludf.DUMMYFUNCTION("""COMPUTED_VALUE"""),1.0) -> 1 | C7: 2025 - 1 | D7: =SUMIFS(Main!$E$2:$E1000,Main!$I$2:$I1000, "="&$B7, Main!$J$2:$J1000, "="&$A7, Main!$C$2:$C1000, "="&D$1) -> -617.99 | E7: =SUMIFS(Main!$E$2:$E1000,Main!$I$2:$I1000, "="&$B7, Main!$J$2:$J1000, "="&$A7, Main!$C$2:$C1000, "="&E$1) -> -1427.85 | F7: =SUMIFS(Main!$E$2:$E1000,Main!$I$2:$I1000, "="&$B7, Main!$J$2:$J1000, "="&$A7, Main!$C$2:$C1000, "="&F$1) -> 0 | G7: =SUMIFS(Main!$E$2:$E1000,Main!$I$2:$I1000, "="&$B7, Main!$J$2:$J1000, "="&$A7, Main!$C$2:$C1000, "="&G$1) -> -8766.66 | H7: =SUMIFS(Main!$E$2:$E1000,Main!$I$2:$I1000, "="&$B7, Main!$J$2:$J1000, "="&$A7, Main!$C$2:$C1000, "="&H$1) -> 0 | I7: =SUMIFS(Main!$E$2:$E1000,Main!$I$2:$I1000, "="&$B7, Main!$J$2:$J1000, "="&$A7, Main!$C$2:$C1000, "="&I$1) -> -3009.4 | J7: =SUMIFS(Main!$E$2:$E1000,Main!$I$2:$I1000, "="&$B7, Main!$J$2:$J1000, "="&$A7, Main!$C$2:$C1000, "="&J$1) -> -67000 | K7: =SUMIFS(Main!$E$2:$E1000,Main!$I$2:$I1000, "="&$B7, Main!$J$2:$J1000, "="&$A7, Main!$C$2:$C1000, "="&K$1) -> -8317 | ... U7: =SUMIFS(Main!$E$2:$E1000,Main!$I$2:$I1000, "="&$B7, Main!$J$2:$J1000, "="&$A7, Main!$C$2:$C1000, "="&U$1) -> 0 | V7: =Y6 -> 98667.78 | W7: =SUMIF($B7:$U7, "<0") -> -94303.71 | X7: =SUMIF($B7:$U7, ">0") -> 10728 | Y7: =V7+W7+X7 -> 15092.07
A8: =IFERROR(__xludf.DUMMYFUNCTION("SPLIT(C8, "" - "")"),2025.0) -> 2025 | B8: =IFERROR(__xludf.DUMMYFUNCTION("""COMPUTED_VALUE"""),2.0) -> 2 | C8: 2025 - 2 | D8: =SUMIFS(Main!$E$2:$E1000,Main!$I$2:$I1000, "="&$B8, Main!$J$2:$J1000, "="&$A8, Main!$C$2:$C1000, "="&D$1) -> -300 | E8: =SUMIFS(Main!$E$2:$E1000,Main!$I$2:$I1000, "="&$B8, Main!$J$2:$J1000, "="&$A8, Main!$C$2:$C1000, "="&E$1) -> -466 | F8: =SUMIFS(Main!$E$2:$E1000,Main!$I$2:$I1000, "="&$B8, Main!$J$2:$J1000, "="&$A8, Main!$C$2:$C1000, "="&F$1) -> 0 | G8: =SUMIFS(Main!$E$2:$E1000,Main!$I$2:$I1000, "="&$B8, Main!$J$2:$J1000, "="&$A8, Main!$C$2:$C1000, "="&G$1) -> -12456.2 | H8: =SUMIFS(Main!$E$2:$E1000,Main!$I$2:$I1000, "="&$B8, Main!$J$2:$J1000, "="&$A8, Main!$C$2:$C1000, "="&H$1) -> 0 | I8: =SUMIFS(Main!$E$2:$E1000,Main!$I$2:$I1000, "="&$B8, Main!$J$2:$J1000, "="&$A8, Main!$C$2:$C1000, "="&I$1) -> 0 | J8: =SUMIFS(Main!$E$2:$E1000,Main!$I$2:$I1000, "="&$B8, Main!$J$2:$J1000, "="&$A8, Main!$C$2:$C1000, "="&J$1) -> -15000 | K8: =SUMIFS(Main!$E$2:$E1000,Main!$I$2:$I1000, "="&$B8, Main!$J$2:$J1000, "="&$A8, Main!$C$2:$C1000, "="&K$1) -> -1709.78 | ... U8: =SUMIFS(Main!$E$2:$E1000,Main!$I$2:$I1000, "="&$B8, Main!$J$2:$J1000, "="&$A8, Main!$C$2:$C1000, "="&U$1) -> 0 | V8: =Y7 -> 15092.07 | W8: =SUMIF($B8:$U8, "<0") -> -40984.52 | X8: =SUMIF($B8:$U8, ">0") -> 159578 | Y8: =V8+W8+X8 -> 133685.55
A9: =IFERROR(__xludf.DUMMYFUNCTION("SPLIT(C9, "" - "")"),2025.0) -> 2025 | B9: =IFERROR(__xludf.DUMMYFUNCTION("""COMPUTED_VALUE"""),3.0) -> 3 | C9: 2025 - 3 | D9: =SUMIFS(Main!$E$2:$E1000,Main!$I$2:$I1000, "="&$B9, Main!$J$2:$J1000, "="&$A9, Main!$C$2:$C1000, "="&D$1) -> 0 | E9: =SUMIFS(Main!$E$2:$E1000,Main!$I$2:$I1000, "="&$B9, Main!$J$2:$J1000, "="&$A9, Main!$C$2:$C1000, "="&E$1) -> -3362.32 | F9: =SUMIFS(Main!$E$2:$E1000,Main!$I$2:$I1000, "="&$B9, Main!$J$2:$J1000, "="&$A9, Main!$C$2:$C1000, "="&F$1) -> 0 | G9: =SUMIFS(Main!$E$2:$E1000,Main!$I$2:$I1000, "="&$B9, Main!$J$2:$J1000, "="&$A9, Main!$C$2:$C1000, "="&G$1) -> -5668.82 | H9: =SUMIFS(Main!$E$2:$E1000,Main!$I$2:$I1000, "="&$B9, Main!$J$2:$J1000, "="&$A9, Main!$C$2:$C1000, "="&H$1) -> -5158 | I9: =SUMIFS(Main!$E$2:$E1000,Main!$I$2:$I1000, "="&$B9, Main!$J$2:$J1000, "="&$A9, Main!$C$2:$C1000, "="&I$1) -> -116.82 | J9: =SUMIFS(Main!$E$2:$E1000,Main!$I$2:$I1000, "="&$B9, Main!$J$2:$J1000, "="&$A9, Main!$C$2:$C1000, "="&J$1) -> -88000 | K9: =SUMIFS(Main!$E$2:$E1000,Main!$I$2:$I1000, "="&$B9, Main!$J$2:$J1000, "="&$A9, Main!$C$2:$C1000, "="&K$1) -> -7270 | ... U9: =SUMIFS(Main!$E$2:$E1000,Main!$I$2:$I1000, "="&$B9, Main!$J$2:$J1000, "="&$A9, Main!$C$2:$C1000, "="&U$1) -> 0 | V9: =Y8 -> 133685.55 | W9: =SUMIF($B9:$U9, "<0") -> -140554.92 | X9: =SUMIF($B9:$U9, ">0") -> 53963 | Y9: =V9+W9+X9 -> 47093.63
A10: =IFERROR(__xludf.DUMMYFUNCTION("SPLIT(C10, "" - "")"),2025.0) -> 2025 | B10: =IFERROR(__xludf.DUMMYFUNCTION("""COMPUTED_VALUE"""),4.0) -> 4 | C10: 2025 - 4 | D10: =SUMIFS(Main!$E$2:$E1000,Main!$I$2:$I1000, "="&$B10, Main!$J$2:$J1000, "="&$A10, Main!$C$2:$C1000, "="&D$1) -> 0 | E10: =SUMIFS(Main!$E$2:$E1000,Main!$I$2:$I1000, "="&$B10, Main!$J$2:$J1000, "="&$A10, Main!$C$2:$C1000, "="&E$1) -> -1671.35 | F10: =SUMIFS(Main!$E$2:$E1000,Main!$I$2:$I1000, "="&$B10, Main!$J$2:$J1000, "="&$A10, Main!$C$2:$C1000, "="&F$1) -> 0 | G10: =SUMIFS(Main!$E$2:$E1000,Main!$I$2:$I1000, "="&$B10, Main!$J$2:$J1000, "="&$A10, Main!$C$2:$C1000, "="&G$1) -> -8543.46 | H10: =SUMIFS(Main!$E$2:$E1000,Main!$I$2:$I1000, "="&$B10, Main!$J$2:$J1000, "="&$A10, Main!$C$2:$C1000, "="&H$1) -> 0 | I10: =SUMIFS(Main!$E$2:$E1000,Main!$I$2:$I1000, "="&$B10, Main!$J$2:$J1000, "="&$A10, Main!$C$2:$C1000, "="&I$1) -> -1036.26 | J10: =SUMIFS(Main!$E$2:$E1000,Main!$I$2:$I1000, "="&$B10, Main!$J$2:$J1000, "="&$A10, Main!$C$2:$C1000, "="&J$1) -> 20000 | K10: =SUMIFS(Main!$E$2:$E1000,Main!$I$2:$I1000, "="&$B10, Main!$J$2:$J1000, "="&$A10, Main!$C$2:$C1000, "="&K$1) -> -38745.53 | ... U10: =SUMIFS(Main!$E$2:$E1000,Main!$I$2:$I1000, "="&$B10, Main!$J$2:$J1000, "="&$A10, Main!$C$2:$C1000, "="&U$1) -> 0 | V10: =Y9 -> 47093.63 | W10: =SUMIF($B10:$U10, "<0") -> -127050.37 | X10: =SUMIF($B10:$U10, ">0") -> 99537 | Y10: =V10+W10+X10 -> 19580.26
A11: =IFERROR(__xludf.DUMMYFUNCTION("SPLIT(C11, "" - "")"),2025.0) -> 2025 | B11: =IFERROR(__xludf.DUMMYFUNCTION("""COMPUTED_VALUE"""),5.0) -> 5 | C11: 2025 - 5 | D11: =SUMIFS(Main!$E$2:$E1000,Main!$I$2:$I1000, "="&$B11, Main!$J$2:$J1000, "="&$A11, Main!$C$2:$C1000, "="&D$1) -> 0 | E11: =SUMIFS(Main!$E$2:$E1000,Main!$I$2:$I1000, "="&$B11, Main!$J$2:$J1000, "="&$A11, Main!$C$2:$C1000, "="&E$1) -> -12603.29 | F11: =SUMIFS(Main!$E$2:$E1000,Main!$I$2:$I1000, "="&$B11, Main!$J$2:$J1000, "="&$A11, Main!$C$2:$C1000, "="&F$1) -> 0 | G11: =SUMIFS(Main!$E$2:$E1000,Main!$I$2:$I1000, "="&$B11, Main!$J$2:$J1000, "="&$A11, Main!$C$2:$C1000, "="&G$1) -> -3579.43 | H11: =SUMIFS(Main!$E$2:$E1000,Main!$I$2:$I1000, "="&$B11, Main!$J$2:$J1000, "="&$A11, Main!$C$2:$C1000, "="&H$1) -> 0 | I11: =SUMIFS(Main!$E$2:$E1000,Main!$I$2:$I1000, "="&$B11, Main!$J$2:$J1000, "="&$A11, Main!$C$2:$C1000, "="&I$1) -> -2974.88 | J11: =SUMIFS(Main!$E$2:$E1000,Main!$I$2:$I1000, "="&$B11, Main!$J$2:$J1000, "="&$A11, Main!$C$2:$C1000, "="&J$1) -> -2990 | K11: =SUMIFS(Main!$E$2:$E1000,Main!$I$2:$I1000, "="&$B11, Main!$J$2:$J1000, "="&$A11, Main!$C$2:$C1000, "="&K$1) -> -43453 | ... U11: =SUMIFS(Main!$E$2:$E1000,Main!$I$2:$I1000, "="&$B11, Main!$J$2:$J1000, "="&$A11, Main!$C$2:$C1000, "="&U$1) -> 0 | V11: =Y10 -> 19580.26 | W11: =SUMIF($B11:$U11, "<0") -> -103740.29 | X11: =SUMIF($B11:$U11, ">0") -> 84373 | Y11: =V11+W11+X11 -> 212.97
A12: =IFERROR(__xludf.DUMMYFUNCTION("SPLIT(C12, "" - "")"),2025.0) -> 2025 | B12: =IFERROR(__xludf.DUMMYFUNCTION("""COMPUTED_VALUE"""),6.0) -> 6 | C12: 2025 - 6 | D12: =SUMIFS(Main!$E$2:$E1000,Main!$I$2:$I1000, "="&$B12, Main!$J$2:$J1000, "="&$A12, Main!$C$2:$C1000, "="&D$1) -> -300 | E12: =SUMIFS(Main!$E$2:$E1000,Main!$I$2:$I1000, "="&$B12, Main!$J$2:$J1000, "="&$A12, Main!$C$2:$C1000, "="&E$1) -> -230.23 | F12: =SUMIFS(Main!$E$2:$E1000,Main!$I$2:$I1000, "="&$B12, Main!$J$2:$J1000, "="&$A12, Main!$C$2:$C1000, "="&F$1) -> 0 | G12: =SUMIFS(Main!$E$2:$E1000,Main!$I$2:$I1000, "="&$B12, Main!$J$2:$J1000, "="&$A12, Main!$C$2:$C1000, "="&G$1) -> -23120 | H12: =SUMIFS(Main!$E$2:$E1000,Main!$I$2:$I1000, "="&$B12, Main!$J$2:$J1000, "="&$A12, Main!$C$2:$C1000, "="&H$1) -> -7120 | I12: =SUMIFS(Main!$E$2:$E1000,Main!$I$2:$I1000, "="&$B12, Main!$J$2:$J1000, "="&$A12, Main!$C$2:$C1000, "="&I$1) -> -1780.44 | J12: =SUMIFS(Main!$E$2:$E1000,Main!$I$2:$I1000, "="&$B12, Main!$J$2:$J1000, "="&$A12, Main!$C$2:$C1000, "="&J$1) -> -30000 | K12: =SUMIFS(Main!$E$2:$E1000,Main!$I$2:$I1000, "="&$B12, Main!$J$2:$J1000, "="&$A12, Main!$C$2:$C1000, "="&K$1) -> -11825.88 | ... U12: =SUMIFS(Main!$E$2:$E1000,Main!$I$2:$I1000, "="&$B12, Main!$J$2:$J1000, "="&$A12, Main!$C$2:$C1000, "="&U$1) -> 0 | V12: =Y11 -> 212.97 | W12: =SUMIF($B12:$U12, "<0") -> -116492.1 | X12: =SUMIF($B12:$U12, ">0") -> 133550 | Y12: =V12+W12+X12 -> 17270.87
A13: =IFERROR(__xludf.DUMMYFUNCTION("SPLIT(C13, "" - "")"),2025.0) -> 2025 | B13: =IFERROR(__xludf.DUMMYFUNCTION("""COMPUTED_VALUE"""),7.0) -> 7 | C13: 2025 - 7 | D13: =SUMIFS(Main!$E$2:$E1000,Main!$I$2:$I1000, "="&$B13, Main!$J$2:$J1000, "="&$A13, Main!$C$2:$C1000, "="&D$1) -> 0 | E13: =SUMIFS(Main!$E$2:$E1000,Main!$I$2:$I1000, "="&$B13, Main!$J$2:$J1000, "="&$A13, Main!$C$2:$C1000, "="&E$1) -> -8972 | F13: =SUMIFS(Main!$E$2:$E1000,Main!$I$2:$I1000, "="&$B13, Main!$J$2:$J1000, "="&$A13, Main!$C$2:$C1000, "="&F$1) -> 0 | G13: =SUMIFS(Main!$E$2:$E1000,Main!$I$2:$I1000, "="&$B13, Main!$J$2:$J1000, "="&$A13, Main!$C$2:$C1000, "="&G$1) -> -3638.66 | H13: =SUMIFS(Main!$E$2:$E1000,Main!$I$2:$I1000, "="&$B13, Main!$J$2:$J1000, "="&$A13, Main!$C$2:$C1000, "="&H$1) -> -7000 | I13: =SUMIFS(Main!$E$2:$E1000,Main!$I$2:$I1000, "="&$B13, Main!$J$2:$J1000, "="&$A13, Main!$C$2:$C1000, "="&I$1) -> -14484.82 | J13: =SUMIFS(Main!$E$2:$E1000,Main!$I$2:$I1000, "="&$B13, Main!$J$2:$J1000, "="&$A13, Main!$C$2:$C1000, "="&J$1) -> 0 | K13: =SUMIFS(Main!$E$2:$E1000,Main!$I$2:$I1000, "="&$B13, Main!$J$2:$J1000, "="&$A13, Main!$C$2:$C1000, "="&K$1) -> -9908 | ... U13: =SUMIFS(Main!$E$2:$E1000,Main!$I$2:$I1000, "="&$B13, Main!$J$2:$J1000, "="&$A13, Main!$C$2:$C1000, "="&U$1) -> 0 | V13: =Y12 -> 17270.87 | W13: =SUMIF($B13:$U13, "<0") -> -90721.9 | X13: =SUMIF($B13:$U13, ">0") -> 96123 | Y13: =V13+W13+X13 -> 22671.97
A14: =IFERROR(__xludf.DUMMYFUNCTION("SPLIT(C14, "" - "")"),2025.0) -> 2025 | B14: =IFERROR(__xludf.DUMMYFUNCTION("""COMPUTED_VALUE"""),8.0) -> 8 | C14: 2025 - 8 | D14: =SUMIFS(Main!$E$2:$E1000,Main!$I$2:$I1000, "="&$B14, Main!$J$2:$J1000, "="&$A14, Main!$C$2:$C1000, "="&D$1) -> 0 | E14: =SUMIFS(Main!$E$2:$E1000,Main!$I$2:$I1000, "="&$B14, Main!$J$2:$J1000, "="&$A14, Main!$C$2:$C1000, "="&E$1) -> -2368.94 | F14: =SUMIFS(Main!$E$2:$E1000,Main!$I$2:$I1000, "="&$B14, Main!$J$2:$J1000, "="&$A14, Main!$C$2:$C1000, "="&F$1) -> 0 | G14: =SUMIFS(Main!$E$2:$E1000,Main!$I$2:$I1000, "="&$B14, Main!$J$2:$J1000, "="&$A14, Main!$C$2:$C1000, "="&G$1) -> -2165.29 | H14: =SUMIFS(Main!$E$2:$E1000,Main!$I$2:$I1000, "="&$B14, Main!$J$2:$J1000, "="&$A14, Main!$C$2:$C1000, "="&H$1) -> -17000 | I14: =SUMIFS(Main!$E$2:$E1000,Main!$I$2:$I1000, "="&$B14, Main!$J$2:$J1000, "="&$A14, Main!$C$2:$C1000, "="&I$1) -> -1947 | J14: =SUMIFS(Main!$E$2:$E1000,Main!$I$2:$I1000, "="&$B14, Main!$J$2:$J1000, "="&$A14, Main!$C$2:$C1000, "="&J$1) -> 0 | K14: =SUMIFS(Main!$E$2:$E1000,Main!$I$2:$I1000, "="&$B14, Main!$J$2:$J1000, "="&$A14, Main!$C$2:$C1000, "="&K$1) -> -17123 | ... U14: =SUMIFS(Main!$E$2:$E1000,Main!$I$2:$I1000, "="&$B14, Main!$J$2:$J1000, "="&$A14, Main!$C$2:$C1000, "="&U$1) -> 7 | V14: =Y13 -> 22671.97 | W14: =SUMIF($B14:$U14, "<0") -> -81634.16 | X14: =SUMIF($B14:$U14, ">0") -> 116168 | Y14: =V14+W14+X14 -> 57205.81
A15: =IFERROR(__xludf.DUMMYFUNCTION("SPLIT(C15, "" - "")"),2025.0) -> 2025 | B15: =IFERROR(__xludf.DUMMYFUNCTION("""COMPUTED_VALUE"""),9.0) -> 9 | C15: 2025 - 9 | D15: =SUMIFS(Main!$E$2:$E1000,Main!$I$2:$I1000, "="&$B15, Main!$J$2:$J1000, "="&$A15, Main!$C$2:$C1000, "="&D$1) -> -1300 | E15: =SUMIFS(Main!$E$2:$E1000,Main!$I$2:$I1000, "="&$B15, Main!$J$2:$J1000, "="&$A15, Main!$C$2:$C1000, "="&E$1) -> -12877 | F15: =SUMIFS(Main!$E$2:$E1000,Main!$I$2:$I1000, "="&$B15, Main!$J$2:$J1000, "="&$A15, Main!$C$2:$C1000, "="&F$1) -> 0 | G15: =SUMIFS(Main!$E$2:$E1000,Main!$I$2:$I1000, "="&$B15, Main!$J$2:$J1000, "="&$A15, Main!$C$2:$C1000, "="&G$1) -> -1729.86 | H15: =SUMIFS(Main!$E$2:$E1000,Main!$I$2:$I1000, "="&$B15, Main!$J$2:$J1000, "="&$A15, Main!$C$2:$C1000, "="&H$1) -> -1000 | I15: =SUMIFS(Main!$E$2:$E1000,Main!$I$2:$I1000, "="&$B15, Main!$J$2:$J1000, "="&$A15, Main!$C$2:$C1000, "="&I$1) -> -11118.22 | J15: =SUMIFS(Main!$E$2:$E1000,Main!$I$2:$I1000, "="&$B15, Main!$J$2:$J1000, "="&$A15, Main!$C$2:$C1000, "="&J$1) -> -25000 | K15: =SUMIFS(Main!$E$2:$E1000,Main!$I$2:$I1000, "="&$B15, Main!$J$2:$J1000, "="&$A15, Main!$C$2:$C1000, "="&K$1) -> -10452.14 | ... U15: =SUMIFS(Main!$E$2:$E1000,Main!$I$2:$I1000, "="&$B15, Main!$J$2:$J1000, "="&$A15, Main!$C$2:$C1000, "="&U$1) -> 0 | V15: =Y14 -> 57205.81 | W15: =SUMIF($B15:$U15, "<0") -> -118707.62 | X15: =SUMIF($B15:$U15, ">0") -> 123823.15 | Y15: =V15+W15+X15 -> 62321.34

Sheet Charts

Sheet Billings
A1: Platform | B1: Status | C1: Type | D1: Cost | E1: Per Month | F1: Per Year
A2: Netflix | B2: Active | C2: Monthly | D2: 645 | E2: =IF(EQ(C2, "Monthly"), D2, D2 / 12) -> 645 | F2: =IF(EQ(C2, "Monthly"), D2 * 12, D2) -> 7740
A3: Google One | B3: Active | C3: Yearly | D3: 6500 | E3: =IF(EQ(C3, "Monthly"), D3, D3 / 12) -> 541.66667 | F3: =IF(EQ(C3, "Monthly"), D3 * 12, D3) -> 6500
A4: YouTube Premium | B4: Active | C4: Monthly | D4: 299 | E4: =IF(EQ(C4, "Monthly"), D4, D4 / 12) -> 299 | F4: =IF(EQ(C4, "Monthly"), D4 * 12, D4) -> 3588
A5: Amazon Prime | B5: Active | C5: Yearly | D5: 799 | E5: =IF(EQ(C5, "Monthly"), D5, D5 / 12) -> 66.583333 | F5: =IF(EQ(C5, "Monthly"), D5 * 12, D5) -> 799
A6: Souled Store | B6: Inactive | C6: Monthly | D6: 66.33 | E6: =IF(EQ(C6, "Monthly"), D6, D6 / 12) -> 66.33 | F6: =IF(EQ(C6, "Monthly"), D6 * 12, D6) -> 795.96
A7: Airtel Postpaid | B7: Active | C7: Monthly | D7: 529.82 | E7: =IF(EQ(C7, "Monthly"), D7, D7 / 12) -> 529.82 | F7: =IF(EQ(C7, "Monthly"), D7 * 12, D7) -> 6357.84
A8: Aitel Wifi | B8: Active | C8: Monthly | D8: 1295.64 | E8: =IF(EQ(C8, "Monthly"), D8, D8 / 12) -> 1295.64 | F8: =IF(EQ(C8, "Monthly"), D8 * 12, D8) -> 15547.68
A9: Airtel DTH | B9: Active | C9: Monthly | D9: 310 | E9: =IF(EQ(C9, "Monthly"), D9, D9 / 12) -> 310 | F9: =IF(EQ(C9, "Monthly"), D9 * 12, D9) -> 3720
A10: Rent | B10: Active | C10: Monthly | D10: 20000 | E10: =IF(EQ(C10, "Monthly"), D10, D10 / 12) -> 20000 | F10: =IF(EQ(C10, "Monthly"), D10 * 12, D10) -> 240000
B11: Active
B12: Active
B13: Active
B14: Active
A16: Totals | C16: Monthly | D16: =SUMIF(C2:C14, "Monthly", D2:D14) -> 23145.79 | E16: =IF(EQ(C16, "Monthly"), D16, D16 / 12) -> 23145.79 | F16: =IF(EQ(C16, "Monthly"), D16 * 12, D16) -> 277749.48
C17: Yearly | D17: =SUMIF(C2:C14, "Yearly", D2:D14) -> 7299 | E17: =IF(EQ(C17, "Monthly"), D17, D17 / 12) -> 608.25 | F17: =IF(EQ(C17, "Monthly"), D17 * 12, D17) -> 7299

Sheet Pivots
